Workbook
Name AÑO: #REF!
Name AÑOVENTA: #REF!
Name BANCO: #REF!
Name CONTRATO: #REF!
Name MES: #REF!
Name MINUTAS: #REF!
Name PAZYSALVO: #REF!
Name PROTOCOLO: #REF!
Name RESIDENCIA: #REF!
Name RESIDENCIA2: #REF!
Name SINOPF: #REF!
Name STATUS: #REF!
Name STATUSBANCO: #REF!
Name VENDEDOR: #REF!

Sheet LISTA PRECIOS
A1: List de precios The Palms Ocean Front
A2: Ud. | B2: Nivel | C2: Modelo | D2: Apartamento | E2: Precio
A3: 1 | B3: 100 | C3: A | D3: 101 | E3: ='BASE DATOS'!AA48 -> 220862.25
A4: 2 | B4: 100 | C4: B | D4: 102 | E4: ='BASE DATOS'!AA49 -> 182000
A5: 3 | B5: 100 | C5: C | D5: 103 | E5: ='BASE DATOS'!AA50 -> 236000
A6: 4 | B6: 100 | C6: C | D6: 104 | E6: ='BASE DATOS'!AA51 -> 212650
A7: 5 | B7: 100 | C7: C | D7: 105 | E7: ='BASE DATOS'!AA52 -> 250000
A8: 6 | B8: 100 | C8: C | D8: 106 | E8: ='BASE DATOS'!AA53 -> 250000
A9: 7 | B9: 100 | C9: C | D9: 107 | E9: ='BASE DATOS'!AA54 -> 220000 | H9: Modelo | I9: Precio
A10: 8 | B10: 100 | C10: C | D10: 108 | E10: ='BASE DATOS'!AA55 -> 217000 | H10: A | I10: =E3+E13+E14+E25+E26+E37+E38+E48+E49+E59 -> 1834364.4
A11: 9 | B11: 100 | C11: C | D11: 109 | E11: ='BASE DATOS'!AA56 -> 221338.98 | H11: B | I11: =E4+E12+E15+E24+E27+E36+E39+E47+E50+E58 -> 1581604.4
A12: 10 | B12: 100 | C12: B | D12: 110 | E12: ='BASE DATOS'!AA57 -> 204000 | H12: C | I12: =E5+E6+E7+E8+E9+E10+E11+E16+E17+E18+E19+E20+E21+E22+E23 -> 3080889
A13: 11 | B13: 100 | C13: A | D13: 111 | E13: ='BASE DATOS'!AA58 -> 194230.69 | F13: =SUM(E3:E13) -> 2408081.9 | H13: C1 | I13: =E28+E29+E30+E31+E32+E33+E34+E35+E40+E41+E42+E43+E46+E51+E52+E53+E54+E57 -> 3452877.8
A14: 12 | B14: 200 | C14: A | D14: 201 | E14: ='BASE DATOS'!AA36 -> 202000 | H14: D | I14: =E44+E45+E55+E56 -> 1097683.5
A15: 13 | B15: 200 | C15: B | D15: 202 | E15: ='BASE DATOS'!AA37 -> 137862 | H15: Total | I15: =SUM(I10:I14) -> 11047419
A16: 14 | B16: 200 | C16: C | D16: 203 | E16: ='BASE DATOS'!AA38 -> 179900
A17: 15 | B17: 200 | C17: C | D17: 204 | E17: ='BASE DATOS'!AA39 -> 184000
A18: 16 | B18: 200 | C18: C | D18: 205 | E18: ='BASE DATOS'!AA40 -> 194000
A19: 17 | B19: 200 | C19: C | D19: 206 | E19: ='BASE DATOS'!AA41 -> 204000
A20: 18 | B20: 200 | C20: C | D20: 207 | E20: ='BASE DATOS'!AA42 -> 201000
A21: 19 | B21: 200 | C21: C | D21: 208 | E21: ='BASE DATOS'!AA43 -> 201000
A22: 20 | B22: 200 | C22: C | D22: 209 | E22: ='BASE DATOS'!AA44 -> 130000
A23: 21 | B23: 200 | C23: C | D23: 210 | E23: ='BASE DATOS'!AA45 -> 180000
A24: 22 | B24: 200 | C24: B | D24: 211 | E24: ='BASE DATOS'!AA46 -> 143389.44
A25: 23 | B25: 200 | C25: A | D25: 212 | E25: ='BASE DATOS'!AA47 -> 185000 | F25: =SUM(E14:E25) -> 2142151.4
A26: 24 | B26: 300 | C26: A | D26: 301 | E26: ='BASE DATOS'!AA24 -> 202000
A27: 25 | B27: 300 | C27: B | D27: 302 | E27: ='BASE DATOS'!AA25 -> 145000
A28: 26 | B28: 300 | C28: C1 | D28: 303 | E28: ='BASE DATOS'!AA26 -> 187000
A29: 27 | B29: 300 | C29: C1 | D29: 304 | E29: ='BASE DATOS'!AA27 -> 183000
A30: 28 | B30: 300 | C30: C1 | D30: 305 | E30: ='BASE DATOS'!AA28 -> 187976.82
A31: 29 | B31: 300 | C31: C1 | D31: 306 | E31: ='BASE DATOS'!AA29 -> 198850
A32: 30 | B32: 300 | C32: C1 | D32: 307 | E32: ='BASE DATOS'!AA30 -> 187000
A33: 31 | B33: 300 | C33: C1 | D33: 308 | E33: ='BASE DATOS'!AA31 -> 185000
A34: 32 | B34: 300 | C34: C1 | D34: 309 | E34: ='BASE DATOS'!AA32 -> 180000
A35: 33 | B35: 300 | C35: C1 | D35: 310 | E35: ='BASE DATOS'!AA33 -> 185000
A36: 34 | B36: 300 | C36: B | D36: 311 | E36: ='BASE DATOS'!AA34 -> 150000
A37: 35 | B37: 300 | C37: A | D37: 312 | E37: ='BASE DATOS'!AA35 -> 172500 | F37: =SUM(E26:E37) -> 2163326.8
A38: 36 | B38: 400 | C38: A | D38: 401 | E38: ='BASE DATOS'!AA13 -> 160000
A39: 37 | B39: 400 | C39: B | D39: 402 | E39: ='BASE DATOS'!AA14 -> 152500
A40: 38 | B40: 400 | C40: C1 | D40: 403 | E40: ='BASE DATOS'!AA15 -> 185270
...

Sheet BASE DATOS
A1: UNIDAD APTO | B1: NIVEL | C1: CLIENTE | D1: RESERVADAS, VENDIDAS | E1: ESTATUS | F1: FECHA DE RESERVA | G1: NÚMERO DE IDENTIDAD | H1: NACIONALIDAD | I1: CLASIFCACIÓN | J1: BROKER | K1: FECHA NACIMIENTO | L1: PERFIL DE INGRESOS | M1: PROFESION | N1: FORMA DE PAGO | O1: PAQUETE DE MUEBLES | P1: EXTRAS | Q1: INCLUIDO EN PRECIO DE VENTA | R1: VALOR DEL PAQUETE | S1: MODELO | T1: AREA CERRADA | U1: AREA BALCON | V1: AREA TOTAL CUANTIFICABLE | W1: VALOR DE BALCON | X1: VALOR DE VENTA DE AREA CERRADA | Y1: CARGO ADICIONAL | Z1: AJUSTE | AA1: VALOR TOTAL | AB1: PRECIO X M2 | AC1: PORCENTAJE ABONADO | AD1: ABONOS RECIBIDOS | AE1: MONTO A GISA | AF1: MONTO A MULTIBANK | AG1: SALDO PENDIENTE | AH1: ESTATUS DE PAGO | AI1: BANCO | AJ1: OFICIAL DE TRÁMITE | AK1: CONTACTO OFICIAL | AL1: ESTATUS2 | AM1: FECHA DE EMISION DE CPP | AN1: FECHA DE VENCIMIENTO CPP | AO1: COMENTARIOS | AP1: MONTO CPP | AQ1: RESERVAS, VENDIDAS | AR1: FECHA DE CONTRATO | AS1: PRECIO DE CONTRATO DE COMPRA Y VENTA | AT1: NUMERO FINCA | AU1: GASTOS LEGALES | AV1: MONTO5 | AW1: SALDO PENDIENTE3 | AX1: ESTATUS6 | AY1: COMENTARIOS ESTATUS LEGAL | AZ1: SOLICITUD DE MINUTA LIBERACIÓN | BA1: MINUTA LIBERACIÓN | BB1: FECHA RECIBIDO MINUTA LIBERACION | BC1: DIAS TRANSCURRIDOS MINUTA LIBERACIÓN | BD1: MINUTA DE VENTA | BE1: FECHA EMISION MINUTA VENTA | BF1: MINUTA DE PRESTAMO | BG1: ACTIVACIÓN DE TRAMITE | BH1: SOLICITUD DE AVALUO | BI1: FECHA DE INSPECCIÓN DE AVALUO | BJ1: ENCARGADO DE AVALUO | BK1: CONFECCION DE PROTOCOLO | BL1: FIRMA CLIENTE | BM1: FIRMA PROMOTOR | BN1: ENVIO A INTERINO | BO1: RECEPCIÓN INTERINO | BP1: DIAS TRANSCURRIDOS INTERINO | BQ1: PAGO IMPUESTO | BR1: IDAAN | BS1: INMUEBLE | BT1: PH | BU1: BANCO CLIENTE | BV1: NOTARIA | BW1: RECEPCIÓN DE NOTARIA | BX1: CIERRE DE NOTARIA | BY1: INGRESO REGISTRO | BZ1: INSCRIPCIÓN REGISTRO | CA1: SOLICITUD DE DESEMBOLSO | CB1: DESEMBOLSO | CC1: FECHA DE ENTREGA
A2: L-501 | B2: 000 | C2: KEVIN FORSYTH | D2: TRASPASADO | E2: INSCRITO Y DESEMBOLSADO | F2: 44986 | G2: HD802468 | H2: CANADIENSE | I2: EXTRANJERO NO RESIDENTE | J2: PANAMA PACIFICA REALTY | K2: 25351 | L2: INDEPENDIENTE | M2: ADMINISTRADOR DE EMPRESAS | N2: CONTADO | O2: SI | P2: SI | Q2: NO | S2: A | T2: 65.93 | U2: 0 | V2: =U2+T2 -> 65.93 | X2: =AB2*T2 -> 168121.5 | AA2: =X2+W2+Y2+Z2 -> 168121.5 | AB2: 2550 | AC2: =((AD2*1)/AA2) -> 1 | AD2: =SUMIFS(Tabla35[Abonos],Tabla35[Lote],Tabla4[[#This Row],[UNIDAD APTO]],Tabla35[Cliente],Tabla4[[#This Row],[CLIENTE]],Tabla35[Concepto],"ABONO")+SUMIFS(Tabla35[Abonos],Tabla35[Lote],Tabla4[[#This Row],[UNIDAD APTO]],Tabla35[Cliente],Tabla4[[#This Row],[CLIENTE]],Tabla35[Concepto],"MULTIBANK") -> 168121.5 | AE2: =Tabla4[[#This Row],[VALOR TOTAL]]-Tabla4[[#This Row],[MONTO A MULTIBANK]] -> 50461.45 | AF2: 117660.05 | AG2: =ABONOS!E3 -> 0 | AH2: {=_xlfn.IFS(Tabla4[[#This Row],[RESERVADAS, VENDIDAS]]="DISPONIBLE","",Tabla4[[#This Row],[SALDO PENDIENTE]]=0,"PAZ Y SALVO",Tabla4[[#This Row],[SALDO PENDIENTE]]=Tabla4[[#This Row],[MONTO CPP]],"COBRO CPP",Tabla4[[#This Row],[SALDO PENDIENTE]]>0,"PENDIENTE")} -> PAZ Y SALVO | AI2: N/A | AJ2: N/A | AK2: N/A | AL2: N/A | AM2: N/A | AN2: N/A | AO2: N/A | AP2: N/A | AQ2: Reservada - Con Contrato | AR2: 45073 | AS2: =AA2 -> 168121.5 | AT2: 30474571 | AU2: GISA | AV2: 1600 | AW2: =ABONOS!O3 -> 0 | AX2: {=_xlfn.IFS(Tabla4[[#This Row],[MONTO5]]=0,"",Tabla4[[#This Row],[SALDO PENDIENTE3]]=0,"PAZ Y SALVO",Tabla4[[#This Row],[SALDO PENDIENTE3]]>0,"PENDIENTE")} -> PAZ Y SALVO | AY2: INSCRITA Y DESEMBOLSADA | AZ2: 45428 | BA2: SI | BB2: 45449 | BC2: =Tabla4[[#This Row],[FECHA RECIBIDO MINUTA LIBERACION]]-Tabla4[[#This Row],[SOLICITUD DE MINUTA LIBERACIÓN]] -> 21 | BD2: SI | BE2: 45440 | BF2: N/A | BG2: N/A | BH2: N/A | BI2: N/A | BJ2: N/A | BK2: 45469 | BL2: 45480 | BM2: 45469 | BN2: 45481 | BO2: 45485 | BP2: =Tabla4[[#This Row],[RECEPCIÓN INTERINO]]-Tabla4[[#This Row],[ENVIO A INTERINO]] -> 4 | BQ2: 45874 | BR2: 45859 | BS2: 45874 | BT2: 45876 | BU2: N/A | BV2: SI | BW2: 45883 | BX2: 45883 | BY2: 45883 | BZ2: 45909 | CA2: N/A | CB2: N/A | CC2: 45377
A3: L-502 | B3: 000 | C3: LANCE Y RADANA MORGAN | D3: TRASPASADO | E3: INSCRITO Y DESEMBOLSADO | F3: 45505 | G3: 571322934 | H3: CANADIENSE | I3: EXTRANJERO NO RESIDENTE | J3: KOYNE | K3: 24967 | L3: INDEPENDIENTE | M3: TECNICO ELECTRODOMESTICOS / ENFERMERA | N3: CONTADO | O3: SI | P3: SI | Q3: SI | S3: B | T3: 59.94 | U3: 0 | V3: =U3+T3 -> 59.94 | X3: =AB3*T3 -> 152847 | AA3: 170000 | AB3: 2550 | AC3: =((AD3*1)/AA3) -> 1 | AD3: =SUMIFS(Tabla35[Abonos],Tabla35[Lote],Tabla4[[#This Row],[UNIDAD APTO]],Tabla35[Cliente],Tabla4[[#This Row],[CLIENTE]],Tabla35[Concepto],"ABONO")+SUMIFS(Tabla35[Abonos],Tabla35[Lote],Tabla4[[#This Row],[UNIDAD APTO]],Tabla35[Cliente],Tabla4[[#This Row],[CLIENTE]],Tabla35[Concepto],"MULTIBANK") -> 170000 | AE3: =Tabla4[[#This Row],[VALOR TOTAL]]-Tabla4[[#This Row],[MONTO A MULTIBANK]] -> 51000 | AF3: =AA3*70% -> 119000 | AG3: =ABONOS!E4 -> 0 | AH3: {=_xlfn.IFS(Tabla4[[#This Row],[RESERVADAS, VENDIDAS]]="DISPONIBLE","",Tabla4[[#This Row],[SALDO PENDIENTE]]=0,"PAZ Y SALVO",Tabla4[[#This Row],[SALDO PENDIENTE]]=Tabla4[[#This Row],[MONTO CPP]],"COBRO CPP",Tabla4[[#This Row],[SALDO PENDIENTE]]>0,"PENDIENTE")} -> PAZ Y SALVO | AI3: N/A | AJ3: N/A | AK3: N/A | AL3: N/A | AM3: N/A | AN3: N/A | AO3: N/A | AP3: N/A | AQ3: Reservada - Con Contrato | AR3: 45519 | AS3: =AA3 -> 170000 | AT3: 30474570 | AU3: GISA | AV3: 1900 | AW3: =ABONOS!O4 -> 0 | AX3: {=_xlfn.IFS(Tabla4[[#This Row],[MONTO5]]=0,"",Tabla4[[#This Row],[SALDO PENDIENTE3]]=0,"PAZ Y SALVO",Tabla4[[#This Row],[SALDO PENDIENTE3]]>0,"PENDIENTE")} -> PAZ Y SALVO | AY3: INSCRITA Y DESEMBOLSADA | AZ3: 45528 | BA3: SI | BB3: 45552 | BC3: =Tabla4[[#This Row],[FECHA RECIBIDO MINUTA LIBERACION]]-Tabla4[[#This Row],[SOLICITUD DE MINUTA LIBERACIÓN]] -> 24 | BD3: SI | BE3: 45549 | BF3: N/A | BG3: N/A | BH3: N/A | BI3: N/A | BJ3: N/A | BK3: 45560 | BL3: 45596 | BM3: 45561 | BN3: 45604 | BO3: 45611 | BP3: =Tabla4[[#This Row],[RECEPCIÓN INTERINO]]-Tabla4[[#This Row],[ENVIO A INTERINO]] -> 7 | BQ3: 45622 | BR3: 45614 | BS3: 45611 | BT3: 45611 | BU3: N/A | BV3: SI | BW3: 45561 | BX3: 45622 | BY3: 45623 | BZ3: 45631 | CA3: N/A | CB3: N/A | CC3: 45600
A4: L-503 | B4: 000 | C4: AARON Y MARSHA EDWARDS | D4: TRASPASADO | E4: INSCRITO Y DESEMBOLSADO | F4: 45200 | G4: 8-1137-1326 | H4: PANAMEÑA | I4: NACIONAL | J4: PANAMA PACIFICA REALTY | K4: 28787 | L4: ASALARIADO | M4: EDUCADOR / DOCTORA | N4: FINANCIAMIENTO | O4: SI | P4: NO | Q4: SI | R4: 15000 | S4: C1 | T4: 73.09 | U4: 0 | V4: =U4+T4 -> 73.09 | X4: =AB4*T4 -> 186379.5 | AA4: 205107.09 | AB4: 2550 | AC4: =((AD4*1)/AA4) -> 1 | AD4: =SUMIFS(Tabla35[Abonos],Tabla35[Lote],Tabla4[[#This Row],[UNIDAD APTO]],Tabla35[Cliente],Tabla4[[#This Row],[CLIENTE]],Tabla35[Concepto],"ABONO")+SUMIFS(Tabla35[Abonos],Tabla35[Lote],Tabla4[[#This Row],[UNIDAD APTO]],Tabla35[Cliente],Tabla4[[#This Row],[CLIENTE]],Tabla35[Concepto],"MULTIBANK") -> 205107.09 | AE4: =Tabla4[[#This Row],[VALOR TOTAL]]-Tabla4[[#This Row],[MONTO A MULTIBANK]] -> 61532.13 | AF4: =Tabla4[[#This Row],[MONTO CPP]] -> 143574.96 | AG4: =ABONOS!E5 -> 0 | AH4: {=_xlfn.IFS(Tabla4[[#This Row],[RESERVADAS, VENDIDAS]]="DISPONIBLE","",Tabla4[[#This Row],[SALDO PENDIENTE]]=0,"PAZ Y SALVO",Tabla4[[#This Row],[SALDO PENDIENTE]]=Tabla4[[#This Row],[MONTO CPP]],"COBRO CPP",Tabla4[[#This Row],[SALDO PENDIENTE]]>0,"PENDIENTE")} -> PAZ Y SALVO | AI4: UNIBANK | AJ4: MONICA OSES | AK4: monica.oses@unibank.com.pa / 6997-8248 | AL4: CON CPP | AM4: 45275 | AN4: N/A | AO4: N/A | AP4: 143574.96 | AQ4: Reservada - Con Contrato | AR4: 45215 | AS4: =AA4 -> 205107.09 | AT4: 30474569 | AU4: UNIBANK | AV4: 5858.13 | AW4: =ABONOS!O5 -> 0 | AX4: {=_xlfn.IFS(Tabla4[[#This Row],[MONTO5]]=0,"",Tabla4[[#This Row],[SALDO PENDIENTE3]]=0,"PAZ Y SALVO",Tabla4[[#This Row],[SALDO PENDIENTE3]]>0,"PENDIENTE")} -> PAZ Y SALVO | AY4: INSCRITA Y DESEMBOLSADA | AZ4: 45492 | BA4: SI | BB4: 45506 | BC4: =Tabla4[[#This Row],[FECHA RECIBIDO MINUTA LIBERACION]]-Tabla4[[#This Row],[SOLICITUD DE MINUTA LIBERACIÓN]] -> 14 | BD4: SI | BE4: 45440 | BF4: SI | BG4: 45499 | BH4: 45499 | BI4: N/A | BJ4: N/A | BK4: 45532 | BL4: 45566 | BM4: 45568 | BN4: 45566 | BO4: 45572 | BP4: =Tabla4[[#This Row],[RECEPCIÓN INTERINO]]-Tabla4[[#This Row],[ENVIO A INTERINO]] -> 6 | BQ4: 45568 | BR4: 45579 | BS4: 45568 | BT4: 45568 | BU4: 45573 | BV4: SI | BW4: N/A | BX4: 45573 | BY4: 45586 | BZ4: 45595 | CA4: 45595 | CB4: 45604 | CC4: 45674
A5: L-504 | B5: 000 | C5: GEORGE WALES Y MAUZIE-LISA WALES | D5: TRASPASADO | E5: INSCRITO Y DESEMBOLSADO | F5: 45580 | G5: RA2827279 / RA2832821 | H5: AUSTRALIANA | I5: EXTRANJERO NO RESIDENTE | J5: PANAMA PACIFICA REALTY | K5: 21194 | L5: INDEPENDIENTE | M5: AGENTE DE VIAJES | N5: CONTADO | O5: SI | P5: NO | Q5: SI | R5: 13500 | S5: C1 | T5: 73.09 | U5: 0 | V5: =U5+T5 -> 73.09 | X5: =AB5*T5 -> 186379.5 | AA5: 204500 | AB5: 2550 | AC5: =((AD5*1)/AA5) -> 1.0000024 | AD5: =SUMIFS(Tabla35[Abonos],Tabla35[Lote],Tabla4[[#This Row],[UNIDAD APTO]],Tabla35[Cliente],Tabla4[[#This Row],[CLIENTE]],Tabla35[Concepto],"ABONO")+SUMIFS(Tabla35[Abonos],Tabla35[Lote],Tabla4[[#This Row],[UNIDAD APTO]],Tabla35[Cliente],Tabla4[[#This Row],[CLIENTE]],Tabla35[Concepto],"MULTIBANK") -> 204500.5 | AE5: =Tabla4[[#This Row],[VALOR TOTAL]]-Tabla4[[#This Row],[MONTO A MULTIBANK]] -> 204500 | AF5: 0 | AG5: =ABONOS!E6 -> -0.5 | AH5: {=_xlfn.IFS(Tabla4[[#This Row],[RESERVADAS, VENDIDAS]]="DISPONIBLE","",Tabla4[[#This Row],[SALDO PENDIENTE]]=0,"PAZ Y SALVO",Tabla4[[#This Row],[SALDO PENDIENTE]]=Tabla4[[#This Row],[MONTO CPP]],"COBRO CPP",Tabla4[[#This Row],[SALDO PENDIENTE]]>0,"PENDIENTE")} -> #N/A | AI5: N/A | AJ5: N/A | AK5: N/A | AL5: N/A | AM5: N/A | AN5: N/A | AO5: N/A | AP5: N/A | AQ5: Reservada - Con Contrato | AR5: 45627 | AS5: =AA5 -> 204500 | AT5: 30474568 | AU5: GISA | AV5: 2070 | AW5: =ABONOS!O6 -> 0 | AX5: {=_xlfn.IFS(Tabla4[[#This Row],[MONTO5]]=0,"",Tabla4[[#This Row],[SALDO PENDIENTE3]]=0,"PAZ Y SALVO",Tabla4[[#This Row],[SALDO PENDIENTE3]]>0,"PENDIENTE")} -> PAZ Y SALVO | AY5: INSCRITA Y DESEMBOLSADA | AZ5: 45954 | BA5: SI | BB5: 45961 | BC5: =Tabla4[[#This Row],[FECHA RECIBIDO MINUTA LIBERACION]]-Tabla4[[#This Row],[SOLICITUD DE MINUTA LIBERACIÓN]] -> 7 | BD5: SI | BE5: 45969 | BF5: N/A | BG5: N/A | BH5: N/A | BI5: N/A | BJ5: N | BK5: 45969 | BL5: 45975 | BM5: 45975 | BN5: 45975 | BO5: 45984 | BP5: =Tabla4[[#This Row],[RECEPCIÓN INTERINO]]-Tabla4[[#This Row],[ENVIO A INTERINO]] -> 9 | BQ5: 45985 | BR5: 45968 | BS5: 45986 | BT5: 45986 | BU5: N/A | BV5: SI | BW5: 45975 | BX5: 45988 | BY5: 45988 | BZ5: 45992 | CA5: N/A | CB5: N/A | CC5: 45946
A6: L-505 | B6: 000 | C6: ALCIBIADES SOLIS | D6: TRASPASADO | E6: INSCRITO Y DESEMBOLSADO | F6: 45108 | G6: 6-700-2182 | H6: PANAMEÑA | I6: NACIONAL | J6: GESPROBAN | K6: 28088 | L6: ASALARIADO | M6: MEDICO | N6: CONTADO | O6: SI | P6: NO | Q6: NO | R6: 15000 | S6: C1 | T6: 73.09 | U6: 0 | V6: =U6+T6 -> 73.09 | X6: =AB6*T6 -> 186379.5 | AA6: =X6+W6+Y6+Z6 -> 186379.5 | AB6: 2550 | AC6: =((AD6*1)/AA6) -> 1 | AD6: =SUMIFS(Tabla35[Abonos],Tabla35[Lote],Tabla4[[#This Row],[UNIDAD APTO]],Tabla35[Cliente],Tabla4[[#This Row],[CLIENTE]],Tabla35[Concepto],"ABONO")+SUMIFS(Tabla35[Abonos],Tabla35[Lote],Tabla4[[#This Row],[UNIDAD APTO]],Tabla35[Cliente],Tabla4[[#This Row],[CLIENTE]],Tabla35[Concepto],"MULTIBANK") -> 186379.5 | AE6: =Tabla4[[#This Row],[VALOR TOTAL]]-Tabla4[[#This Row],[MONTO A MULTIBANK]] -> 55913.85 | AF6: =AA6*70% -> 130465.65 | AG6: =ABONOS!E7 -> 0 | AH6: {=_xlfn.IFS(Tabla4[[#This Row],[RESERVADAS, VENDIDAS]]="DISPONIBLE","",Tabla4[[#This Row],[SALDO PENDIENTE]]=0,"PAZ Y SALVO",Tabla4[[#This Row],[SALDO PENDIENTE]]=Tabla4[[#This Row],[MONTO CPP]],"COBRO CPP",Tabla4[[#This Row],[SALDO PENDIENTE]]>0,"PENDIENTE")} -> PAZ Y SALVO | AI6: N/A | AJ6: N/A | AK6: N/A | AL6: N/A | AM6: N/A | AN6: N/A | AO6: N/A | AP6: N/A | AQ6: Reservada - Con Contrato | AR6: 45054 | AS6: =AA6 -> 186379.5 | AT6: 30474567 | AU6: GISA | AV6: 1400 | AW6: =ABONOS!O7 -> 0 | AX6: {=_xlfn.IFS(Tabla4[[#This Row],[MONTO5]]=0,"",Tabla4[[#This Row],[SALDO PENDIENTE3]]=0,"PAZ Y SALVO",Tabla4[[#This Row],[SALDO PENDIENTE3]]>0,"PENDIENTE")} -> PAZ Y SALVO | AY6: INSCRITA Y DESEMBOLSADA | AZ6: 45428 | BA6: SI | BB6: 45449 | BC6: =Tabla4[[#This Row],[FECHA RECIBIDO MINUTA LIBERACION]]-Tabla4[[#This Row],[SOLICITUD DE MINUTA LIBERACIÓN]] -> 21 | BD6: SI | BE6: 45450 | BF6: N/A | BG6: N/A | BH6: N/A | BI6: N/A | BJ6: N/A | BK6: 45449 | BL6: 45458 | BM6: 45454 | BN6: 45461 | BO6: 45469 | BP6: =Tabla4[[#This Row],[RECEPCIÓN INTERINO]]-Tabla4[[#This Row],[ENVIO A INTERINO]] -> 8 | BQ6: 45471 | BR6: 45485 | BS6: 45469 | BT6: 45470 | BU6: N/A | BV6: SI | BW6: 45450 | BX6: 45475 | BY6: 45358 | BZ6: 45488 | CA6: N/A | CB6: N/A | CC6: 45422
A7: L-506 | B7: 000 | C7: ERIC WHITAKER | D7: TRASPASADO | E7: INSCRITO Y DESEMBOLSADO | F7: 45139 | G7: 674360401 | H7: ESTADOUNIDENSE | I7: EXTRANJERO NO RESIDENTE | J7: DOO PANAMA | K7: 29184 | L7: INDEPENDIENTE | M7: TERAPEUTA | N7: CONTADO | O7: SI | P7: NO | Q7: SI | S7: C1 | T7: 73.96 | U7: 0 | V7: =U7+T7 -> 73.96 | X7: 209100 | AA7: =X7+W7+Y7+Z7 -> 209100 | AB7: 2550 | AC7: =((AD7*1)/AA7) -> 1 | AD7: =SUMIFS(Tabla35[Abonos],Tabla35[Lote],Tabla4[[#This Row],[UNIDAD APTO]],Tabla35[Cliente],Tabla4[[#This Row],[CLIENTE]],Tabla35[Concepto],"ABONO")+SUMIFS(Tabla35[Abonos],Tabla35[Lote],Tabla4[[#This Row],[UNIDAD APTO]],Tabla35[Cliente],Tabla4[[#This Row],[CLIENTE]],Tabla35[Concepto],"MULTIBANK") -> 209100 | AE7: =Tabla4[[#This Row],[VALOR TOTAL]]-Tabla4[[#This Row],[MONTO A MULTIBANK]] -> 209100 | AF7: 0 | AG7: =ABONOS!E8 -> 0 | AH7: {=_xlfn.IFS(Tabla4[[#This Row],[RESERVADAS, VENDIDAS]]="DISPONIBLE","",Tabla4[[#This Row],[SALDO PENDIENTE]]=0,"PAZ Y SALVO",Tabla4[[#This Row],[SALDO PENDIENTE]]=Tabla4[[#This Row],[MONTO CPP]],"COBRO CPP",Tabla4[[#This Row],[SALDO PENDIENTE]]>0,"PENDIENTE")} -> PAZ Y SALVO | AI7: N/A | AJ7: N/A | AK7: N/A | AL7: N/A | AM7: N/A | AN7: N/A | AO7: ACUERDO FINANCIAMIENTO INTERNO | AP7: N/A | AQ7: Reservada - Con Contrato | AR7: 45189 | AS7: =AA7 -> 209100 | AT7: 30474566 | AU7: GISA | AV7: 3427.6 | AW7: =ABONOS!O8 -> 0 | AX7: {=_xlfn.IFS(Tabla4[[#This Row],[MONTO5]]=0,"",Tabla4[[#This Row],[SALDO PENDIENTE3]]=0,"PAZ Y SALVO",Tabla4[[#This Row],[SALDO PENDIENTE3]]>0,"PENDIENTE")} -> PAZ Y SALVO | AY7: INSCRITA Y DESEMBOLSADA | AZ7: 45862 | BA7: SI | BB7: 45869 | BC7: =Tabla4[[#This Row],[FECHA RECIBIDO MINUTA LIBERACION]]-Tabla4[[#This Row],[SOLICITUD DE MINUTA LIBERACIÓN]] -> 7 | BD7: SI | BE7: 45926 | BF7: N/A | BG7: N/A | BH7: N/A | BI7: N/A | BJ7: N/A | BK7: 45944 | BL7: 45958 | BM7: 45957 | BN7: 45959 | BO7: 45969 | BP7: =Tabla4[[#This Row],[RECEPCIÓN INTERINO]]-Tabla4[[#This Row],[ENVIO A INTERINO]] -> 10 | BQ7: 45974 | BR7: 45968 | BS7: 45982 | BT7: 45979 | BU7: N/A | BV7: SI | BW7: 45957 | BX7: 45980 | BY7: 45982 | BZ7: 46055 | CA7: N/A | CB7: N/A | CC7: 45529
A8: L-507 | B8: 000 | C8: BRUNO LA GROTTA | D8: TRASPASADO | E8: INSCRITO Y DESEMBOLSADO | F8: 44986 | G8: 8-238-1798 | H8: PANAMEÑA | I8: NACIONAL | J8: GESPROBAN | K8: 23907 | L8: INDEPENDIENTE | M8: ARQUITECTO | N8: CONTADO | O8: SI | P8: SI | Q8: N/A | R8: 0 | S8: D | T8: 110.82 | U8: 0 | V8: =U8+T8 -> 110.82 | X8: =AB8*T8 -> 270000 | AA8: =X8+W8+Y8+Z8 -> 270000 | AB8: 2436.3833 | AC8: =((AD8*1)/AA8) -> 1 | AD8: =SUMIFS(Tabla35[Abonos],Tabla35[Lote],Tabla4[[#This Row],[UNIDAD APTO]],Tabla35[Cliente],Tabla4[[#This Row],[CLIENTE]],Tabla35[Concepto],"ABONO")+SUMIFS(Tabla35[Abonos],Tabla35[Lote],Tabla4[[#This Row],[UNIDAD APTO]],Tabla35[Cliente],Tabla4[[#This Row],[CLIENTE]],Tabla35[Concepto],"MULTIBANK") -> 270000 | AE8: =Tabla4[[#This Row],[VALOR TOTAL]]-Tabla4[[#This Row],[MONTO A MULTIBANK]] -> 116000 | AF8: =(AA8-50000)*70% -> 154000 | AG8: =ABONOS!E9 -> 0 | AH8: {=_xlfn.IFS(Tabla4[[#This Row],[RESERVADAS, VENDIDAS]]="DISPONIBLE","",Tabla4[[#This Row],[SALDO PENDIENTE]]=0,"PAZ Y SALVO",Tabla4[[#This Row],[SALDO PENDIENTE]]=Tabla4[[#This Row],[MONTO CPP]],"COBRO CPP",Tabla4[[#This Row],[SALDO PENDIENTE]]>0,"PENDIENTE")} -> PAZ Y SALVO | AI8: N/A | AJ8: N/A | AK8: N/A | AL8: N/A | AM8: N/A | AN8: N/A | AO8: N/A | AP8: N/A | AQ8: Reservada - Con Contrato | AR8: 44973 | AS8: =AA8 -> 270000 | AT8: 30474565 | AU8: GISA | AV8: 1950 | AW8: =ABONOS!O9 -> 0 | AX8: {=_xlfn.IFS(Tabla4[[#This Row],[MONTO5]]=0,"",Tabla4[[#This Row],[SALDO PENDIENTE3]]=0,"PAZ Y SALVO",Tabla4[[#This Row],[SALDO PENDIENTE3]]>0,"PENDIENTE")} -> PAZ Y SALVO | AY8: INSCRITA Y DESEMBOLSADA, POR ENTREGAR ESCRITURA PUBLICA | AZ8: 45779 | BA8: SI | BB8: 45785 | BC8: =Tabla4[[#This Row],[FECHA RECIBIDO MINUTA LIBERACION]]-Tabla4[[#This Row],[SOLICITUD DE MINUTA LIBERACIÓN]] -> 6 | BD8: SI | BE8: 45710 | BF8: N/A | BG8: N/A | BH8: N/A | BI8: N/A | BJ8: N/A | BK8: 45710 | BL8: 45799 | BM8: 45799 | BN8: 45799 | BO8: 45806 | BP8: =Tabla4[[#This Row],[RECEPCIÓN INTERINO]]-Tabla4[[#This Row],[ENVIO A INTERINO]] -> 7 | BQ8: 45820 | BR8: 45825 | BS8: 45820 | BT8: 45820 | BU8: N/A | BV8: SI | BW8: 45796 | BX8: 45818 | BY8: 45827 | BZ8: 45834 | CA8: N/A | CB8: N/A | CC8: 45330
A9: L-508 | B9: 000 | C9: PAUL Y RENATE MIANO | D9: TRASPASADO | E9: INSCRITO Y DESEMBOLSADO | F9: 45017 | G9: 668898941 / 668898940 | H9: ESTADOUNIDENSE | I9: EXTRANJERO NO RESIDENTE | J9: PANAMA PACIFICA REALTY | K9: 18346 | L9: INDEPENDIENTE | M9: BIENES RAICES / CONTABLE | N9: CONTADO | O9: SI | P9: SI | Q9: SI | R9: 20000 | S9: D | T9: 109.27 | U9: 0 | V9: =U9+T9 -> 109.27 | X9: =AB9*T9 -> 278638.5 | AA9: 278683.5 | AB9: 2550 | AC9: =((AD9*1)/AA9) -> 1 | AD9: =SUMIFS(Tabla35[Abonos],Tabla35[Lote],Tabla4[[#This Row],[UNIDAD APTO]],Tabla35[Cliente],Tabla4[[#This Row],[CLIENTE]],Tabla35[Concepto],"ABONO")+SUMIFS(Tabla35[Abonos],Tabla35[Lote],Tabla4[[#This Row],[UNIDAD APTO]],Tabla35[Cliente],Tabla4[[#This Row],[CLIENTE]],Tabla35[Concepto],"MULTIBANK") -> 278683.5 | AE9: =Tabla4[[#This Row],[VALOR TOTAL]]-Tabla4[[#This Row],[MONTO A MULTIBANK]] -> 83592 | AF9: 195091.5 | AG9: =ABONOS!E10 -> 0 | AH9: {=_xlfn.IFS(Tabla4[[#This Row],[RESERVADAS, VENDIDAS]]="DISPONIBLE","",Tabla4[[#This Row],[SALDO PENDIENTE]]=0,"PAZ Y SALVO",Tabla4[[#This Row],[SALDO PENDIENTE]]=Tabla4[[#This Row],[MONTO CPP]],"COBRO CPP",Tabla4[[#This Row],[SALDO PENDIENTE]]>0,"PENDIENTE")} -> PAZ Y SALVO | AI9: N/A | AJ9: N/A | AK9: N/A | AL9: N/A | AM9: N/A | AN9: N/A | AO9: N/A | AP9: N/A | AQ9: Reservada - Con Contrato | AR9: 45040 | AS9: =AA9 -> 278683.5 | AT9: 30474564 | AU9: GISA | AV9: 1950 | AW9: =ABONOS!O10 -> 0 | AX9: {=_xlfn.IFS(Tabla4[[#This Row],[MONTO5]]=0,"",Tabla4[[#This Row],[SALDO PENDIENTE3]]=0,"PAZ Y SALVO",Tabla4[[#This Row],[SALDO PENDIENTE3]]>0,"PENDIENTE")} -> PAZ Y SALVO | AY9: INSCRITA Y DESEMBOLSADA | AZ9: 45428 | BA9: SI | BB9: 45449 | BC9: =Tabla4[[#This Row],[FECHA RECIBIDO MINUTA LIBERACION]]-Tabla4[[#This Row],[SOLICITUD DE MINUTA LIBERACIÓN]] -> 21 | BD9: SI | BE9: 45414 | BF9: N/A | BG9: N/A | BH9: N/A | BI9: N/A | BJ9: N/A | BK9: 45461 | BL9: 45468 | BM9: 45467 | BN9: 45471 | BO9: 45477 | BP9: =Tabla4[[#This Row],[RECEPCIÓN INTERINO]]-Tabla4[[#This Row],[ENVIO A INTERINO]] -> 6 | BQ9: 45482 | BR9: 45485 | BS9: 45485 | BT9: 45482 | BU9: N/A | BV9: SI | BW9: 45462 | BX9: 45483 | BY9: 45485 | BZ9: 45499 | CA9: N/A | CB9: N/A | CC9: 45357
A10: L-509 | B10: 000 | C10: DAYANARA RÍOS | D10: TRASPASADO | E10: INSCRITO Y DESEMBOLSADO | F10: 45108 | G10: 8-729-1993 | H10: PANAMEÑA | I10: NACIONAL | J10: GESPROBAN | K10: 29007 | L10: ASALARIADO | M10: CONTADOR PUBLICO AUTORIZADO | N10: FINANCIAMIENTO | O10: NO | P10: NO | Q10: N/A | R10: 0 | S10: C1 | T10: 73.09 | U10: 0 | V10: =U10+T10 -> 73.09 | X10: =AB10*T10 -> 186379.5 | AA10: =X10+W10+Y10+Z10 -> 186379.5 | AB10: 2550 | AC10: =((AD10*1)/AA10) -> 1 | AD10: =SUMIFS(Tabla35[Abonos],Tabla35[Lote],Tabla4[[#This Row],[UNIDAD APTO]],Tabla35[Cliente],Tabla4[[#This Row],[CLIENTE]],Tabla35[Concepto],"ABONO")+SUMIFS(Tabla35[Abonos],Tabla35[Lote],Tabla4[[#This Row],[UNIDAD APTO]],Tabla35[Cliente],Tabla4[[#This Row],[CLIENTE]],Tabla35[Concepto],"MULTIBANK") -> 186379.5 | AE10: =Tabla4[[#This Row],[VALOR TOTAL]]-Tabla4[[#This Row],[MONTO A MULTIBANK]] -> 37275.9 | AF10: =Tabla4[[#This Row],[MONTO CPP]] -> 149103.6 | AG10: =ABONOS!E11 -> 0 | AH10: {=_xlfn.IFS(Tabla4[[#This Row],[RESERVADAS, VENDIDAS]]="DISPONIBLE","",Tabla4[[#This Row],[SALDO PENDIENTE]]=0,"PAZ Y SALVO",Tabla4[[#This Row],[SALDO PENDIENTE]]=Tabla4[[#This Row],[MONTO CPP]],"COBRO CPP",Tabla4[[#This Row],[SALDO PENDIENTE]]>0,"PENDIENTE")} -> PAZ Y SALVO | AI10: TOWERBANK | AJ10: KERIMA CHONG | AK10: kchong@towerbank.com / 269-6900 | AL10: CON CPP | AM10: 45133 | AN10: 45495 | AO10: CON CPP | AP10: 149103.6 | AQ10: Reservada - Con Contrato | AR10: 45145 | AS10: =AA10 -> 186379.5 | AT10: 30474563 | AU10: TOWERBANK | AV10: BANCO | AW10: =ABONOS!O11 -> 0 | AX10: {=_xlfn.IFS(Tabla4[[#This Row],[MONTO5]]=0,"",Tabla4[[#This Row],[SALDO PENDIENTE3]]=0,"PAZ Y SALVO",Tabla4[[#This Row],[SALDO PENDIENTE3]]>0,"PENDIENTE")} -> PAZ Y SALVO | AY10: INSCRITA Y DESEMBOLSADA | AZ10: 45428 | BA10: SI | BB10: 45455 | BC10: =Tabla4[[#This Row],[FECHA RECIBIDO MINUTA LIBERACION]]-Tabla4[[#This Row],[SOLICITUD DE MINUTA LIBERACIÓN]] -> 27 | BD10: SI | BE10: 45440 | BF10: SI | BG10: 45435 | BH10: SI | BI10: SI | BJ10: SI | BK10: 45476 | BL10: 45472 | BM10: 45477 | BN10: 45477 | BO10: 45481 | BP10: =Tabla4[[#This Row],[RECEPCIÓN INTERINO]]-Tabla4[[#This Row],[ENVIO A INTERINO]] -> 4 | BQ10: 45477 | BR10: 45457 | BS10: 45478 | BT10: 45478 | BU10: 45481 | BV10: SI | BW10: 45470 | BX10: 45484 | BY10: 45485 | BZ10: 45488 | CA10: 45488 | CB10: 45491 | CC10: 45499
A11: L-510 | B11: 000 | C11: NICHOLAS CHILLEMI | D11: TRASPASADO | E11: INSCRITO Y DESEMBOLSADO | F11: 45261 | G11: 533608824 | H11: ESTADOUNIDENSE | I11: EXTRANJERO NO RESIDENTE | J11: PANAMA EQUITY | K11: 20482 | L11: INDEPENDIENTE | M11: BIENES RAICES | N11: CONTADO | O11: SI | P11: SI | Q11: NO | R11: 12000 | S11: B | T11: 59.94 | U11: 0 | V11: =U11+T11 -> 59.94 | X11: =AB11*T11 -> 152847 | AA11: 150000 | AB11: 2550 | AC11: =((AD11*1)/AA11) -> 1 | AD11: =SUMIFS(Tabla35[Abonos],Tabla35[Lote],Tabla4[[#This Row],[UNIDAD APTO]],Tabla35[Cliente],Tabla4[[#This Row],[CLIENTE]],Tabla35[Concepto],"ABONO")+SUMIFS(Tabla35[Abonos],Tabla35[Lote],Tabla4[[#This Row],[UNIDAD APTO]],Tabla35[Cliente],Tabla4[[#This Row],[CLIENTE]],Tabla35[Concepto],"MULTIBANK") -> 150000 | AE11: =Tabla4[[#This Row],[VALOR TOTAL]]-Tabla4[[#This Row],[MONTO A MULTIBANK]] -> 45000 | AF11: =Tabla4[[#This Row],[MONTO CPP]] -> 105000 | AG11: =ABONOS!E12 -> 0 | AH11: {=_xlfn.IFS(Tabla4[[#This Row],[RESERVADAS, VENDIDAS]]="DISPONIBLE","",Tabla4[[#This Row],[SALDO PENDIENTE]]=0,"PAZ Y SALVO",Tabla4[[#This Row],[SALDO PENDIENTE]]=Tabla4[[#This Row],[MONTO CPP]],"COBRO CPP",Tabla4[[#This Row],[SALDO PENDIENTE]]>0,"PENDIENTE")} -> PAZ Y SALVO | AI11: BANCO ALIADO | AJ11: KATHERINE MARTNEZ | AK11: katherine.martinez@bancoaliado.com / 6948-4733 | AL11: CON CPP | AM11: 45377 | AN11: 45558 | AO11: CON CPP | AP11: 105000 | AQ11: Reservada - Con Contrato | AR11: 45337 | AS11: =AA11 -> 150000 | AT11: 30474562 | AU11: GISA | AV11: 1525 | AW11: =ABONOS!O12 -> 0 | AX11: {=_xlfn.IFS(Tabla4[[#This Row],[MONTO5]]=0,"",Tabla4[[#This Row],[SALDO PENDIENTE3]]=0,"PAZ Y SALVO",Tabla4[[#This Row],[SALDO PENDIENTE3]]>0,"PENDIENTE")} -> PAZ Y SALVO | AY11: INSCRITA Y DESEMBOLSADA | AZ11: 45428 | BA11: SI | BB11: 45455 | BC11: =Tabla4[[#This Row],[FECHA RECIBIDO MINUTA LIBERACION]]-Tabla4[[#This Row],[SOLICITUD DE MINUTA LIBERACIÓN]] -> 27 | BD11: SI | BE11: 45446 | BF11: N/A | BG11: N/A | BH11: N/A | BI11: N/A | BJ11: N/A | BK11: 45464 | BL11: 45479 | BM11: 45478 | BN11: 45483 | BO11: 45485 | BP11: =Tabla4[[#This Row],[RECEPCIÓN INTERINO]]-Tabla4[[#This Row],[ENVIO A INTERINO]] -> 2 | BQ11: 45489 | BR11: 45484 | BS11: 45489 | BT11: 45488 | BU11: N/A | BV11: SI | BW11: 45464 | BX11: 45489 | BY11: 45490 | BZ11: 45496 | CA11: 45496 | CB11: 45499 | CC11: 45502
A12: L-511 | B12: 000 | C12: JEANETTE MUNROE | D12: TRASPASADO | E12: INSCRITO Y DESEMBOLSADO | F12: 44986 | G12: 542879367 | H12: ESTADOUNIDENSE | I12: EXTRANJERO NO RESIDENTE | J12: PANAMA PACIFICA REALTY | K12: 23337 | L12: INDEPENDIENTE | M12: ADMINISTRADOR DE EMPRESAS | N12: CONTADO | O12: SI | P12: NO | Q12: SI | S12: A | T12: 65.93 | U12: 0 | V12: =U12+T12 -> 65.93 | X12: =AB12*T12 -> 168121.5 | AA12: =X12+W12+Y12+Z12 -> 168121.5 | AB12: 2550 | AC12: =((AD12*1)/AA12) -> 1 | AD12: =SUMIFS(Tabla35[Abonos],Tabla35[Lote],Tabla4[[#This Row],[UNIDAD APTO]],Tabla35[Cliente],Tabla4[[#This Row],[CLIENTE]],Tabla35[Concepto],"ABONO")+SUMIFS(Tabla35[Abonos],Tabla35[Lote],Tabla4[[#This Row],[UNIDAD APTO]],Tabla35[Cliente],Tabla4[[#This Row],[CLIENTE]],Tabla35[Concepto],"MULTIBANK") -> 168121.5 | AE12: =Tabla4[[#This Row],[VALOR TOTAL]]-Tabla4[[#This Row],[MONTO A MULTIBANK]] -> 58842.525 | AF12: =AA12*65% -> 109278.98 | AG12: =ABONOS!E13 -> 0 | AH12: {=_xlfn.IFS(Tabla4[[#This Row],[RESERVADAS, VENDIDAS]]="DISPONIBLE","",Tabla4[[#This Row],[SALDO PENDIENTE]]=0,"PAZ Y SALVO",Tabla4[[#This Row],[SALDO PENDIENTE]]=Tabla4[[#This Row],[MONTO CPP]],"COBRO CPP",Tabla4[[#This Row],[SALDO PENDIENTE]]>0,"PENDIENTE")} -> PAZ Y SALVO | AI12: N/A | AJ12: N/A | AK12: N/A | AL12: N/A | AM12: N/A | AN12: N/A | AO12: N/A | AP12: N/A | AQ12: Reservada - Con Contrato | AR12: 45058 | AS12: =AA12 -> 168121.5 | AT12: 30474561 | AU12: GISA | AV12: 1600 | AW12: =ABONOS!O13 -> 0 | AX12: {=_xlfn.IFS(Tabla4[[#This Row],[MONTO5]]=0,"",Tabla4[[#This Row],[SALDO PENDIENTE3]]=0,"PAZ Y SALVO",Tabla4[[#This Row],[SALDO PENDIENTE3]]>0,"PENDIENTE")} -> PAZ Y SALVO | AY12: INSCRITA Y DESEMBOLSADA | AZ12: 45478 | BA12: SI | BB12: 45497 | BC12: =Tabla4[[#This Row],[FECHA RECIBIDO MINUTA LIBERACION]]-Tabla4[[#This Row],[SOLICITUD DE MINUTA LIBERACIÓN]] -> 19 | BD12: SI | BE12: 45496 | BF12: N/A | BG12: N/A | BH12: N/A | BI12: N/A | BJ12: N/A | BK12: 45477 | BL12: 45478 | BM12: 45477 | BN12: 45524 | BO12: 45533 | BP12: =Tabla4[[#This Row],[RECEPCIÓN INTERINO]]-Tabla4[[#This Row],[ENVIO A INTERINO]] -> 9 | BQ12: 1396933 | BR12: 45539 | BS12: 45539 | BT12: 45542 | BU12: N/A | BV12: SI | BW12: 45477 | BX12: 45541 | BY12: 45545 | BZ12: 45554 | CA12: N/A | CB12: N/A | CC12: 45572
A13: L-401 | B13: -100 | C13: ROBERT RODRIGUEZ | D13: TRASPASADO | E13: INSCRITO Y DESEMBOLSADO | F13: 44986 | G13: 6-711-23 | H13: PANAMEÑA | I13: NACIONAL | J13: GESPROBAN | K13: 31415 | L13: ASALARIADO | M13: ADMINISTRADOR DE EMPRESAS | N13: FINANCIAMIENTO | O13: SI | P13: NO | Q13: NO | S13: A | T13: 65.93 | U13: 0 | V13: =U13+T13 -> 65.93 | X13: =AB13*T13 -> 161528.5 | Z13: -1528.5 | AA13: =X13+W13+Y13+Z13 -> 160000 | AB13: 2450 | AC13: =((AD13*1)/AA13) -> 1 | AD13: =SUMIFS(Tabla35[Abonos],Tabla35[Lote],Tabla4[[#This Row],[UNIDAD APTO]],Tabla35[Cliente],Tabla4[[#This Row],[CLIENTE]],Tabla35[Concepto],"ABONO")+SUMIFS(Tabla35[Abonos],Tabla35[Lote],Tabla4[[#This Row],[UNIDAD APTO]],Tabla35[Cliente],Tabla4[[#This Row],[CLIENTE]],Tabla35[Concepto],"MULTIBANK") -> 160000 | AE13: =Tabla4[[#This Row],[VALOR TOTAL]]-Tabla4[[#This Row],[MONTO A MULTIBANK]] -> 56000 | AF13: =AA13*65% -> 104000 | AG13: =ABONOS!E14 -> 0 | AH13: {=_xlfn.IFS(Tabla4[[#This Row],[RESERVADAS, VENDIDAS]]="DISPONIBLE","",Tabla4[[#This Row],[SALDO PENDIENTE]]=0,"PAZ Y SALVO",Tabla4[[#This Row],[SALDO PENDIENTE]]=Tabla4[[#This Row],[MONTO CPP]],"COBRO CPP",Tabla4[[#This Row],[SALDO PENDIENTE]]>0,"PENDIENTE")} -> PAZ Y SALVO | AI13: SCOTIABANK | AJ13: RICARDO HERRERA | AK13: ricardo.herrera@pa.scotiabank.com / 6349-7898 | AL13: CON CPP | AM13: 45407 | AN13: 45772 | AO13: CON CPP | AP13: 86000 | AQ13: Reservada - Con Contrato | AR13: 45051 | AS13: =AA13 -> 160000 | AT13: 30474582 | AU13: SCOTIABANK | AV13: BANCO | AW13: =ABONOS!O14 -> 0 | AX13: {=_xlfn.IFS(Tabla4[[#This Row],[MONTO5]]=0,"",Tabla4[[#This Row],[SALDO PENDIENTE3]]=0,"PAZ Y SALVO",Tabla4[[#This Row],[SALDO PENDIENTE3]]>0,"PENDIENTE")} -> PAZ Y SALVO | AY13: INSCRITA Y DESEMBOLSADA | AZ13: 45478 | BA13: SI | BB13: 45496 | BC13: =Tabla4[[#This Row],[FECHA RECIBIDO MINUTA LIBERACION]]-Tabla4[[#This Row],[SOLICITUD DE MINUTA LIBERACIÓN]] -> 18 | BD13: SI | BE13: 45492 | BF13: SI | BG13: 45492 | BH13: SI | BI13: 45476 | BJ13: SI | BK13: 45528 | BL13: 45525 | BM13: 45526 | BN13: 45530 | BO13: 45531 | BP13: =Tabla4[[#This Row],[RECEPCIÓN INTERINO]]-Tabla4[[#This Row],[ENVIO A INTERINO]] -> 1 | BQ13: 45527 | BR13: 45537 | BS13: 45539 | BT13: 45526 | BU13: 45558 | BV13: SI | BW13: 45528 | BX13: 45544 | BY13: 45547 | BZ13: 45551 | CA13: 45551 | CB13: 45555 | CC13: 45811
A14: L-402 | B14: -100 | C14: EDGAR UREÑA | D14: TRASPASADO | E14: INSCRITO Y DESEMBOLSADO | F14: 45413 | G14: 8-735-347 | H14: PANAMEÑA | I14: NACIONAL | J14: GESPROBAN | K14: 29281 | L14: ASALARIADO | M14: CIRUJANO MAXILOFACIAL | N14: FINANCIAMIENTO | S14: B | T14: 59.94 | U14: 0 | V14: =U14+T14 -> 59.94 | X14: =AB14*T14 -> 146853 | AA14: 152500 | AB14: 2450 | AC14: =((AD14*1)/AA14) -> 1 | AD14: =SUMIFS(Tabla35[Abonos],Tabla35[Lote],Tabla4[[#This Row],[UNIDAD APTO]],Tabla35[Cliente],Tabla4[[#This Row],[CLIENTE]],Tabla35[Concepto],"ABONO")+SUMIFS(Tabla35[Abonos],Tabla35[Lote],Tabla4[[#This Row],[UNIDAD APTO]],Tabla35[Cliente],Tabla4[[#This Row],[CLIENTE]],Tabla35[Concepto],"MULTIBANK") -> 152500 | AE14: =Tabla4[[#This Row],[VALOR TOTAL]]-Tabla4[[#This Row],[MONTO A MULTIBANK]] -> 30500 | AF14: =AA14*80% -> 122000 | AG14: =ABONOS!E15 -> 0 | AH14: {=_xlfn.IFS(Tabla4[[#This Row],[RESERVADAS, VENDIDAS]]="DISPONIBLE","",Tabla4[[#This Row],[SALDO PENDIENTE]]=0,"PAZ Y SALVO",Tabla4[[#This Row],[SALDO PENDIENTE]]=Tabla4[[#This Row],[MONTO CPP]],"COBRO CPP",Tabla4[[#This Row],[SALDO PENDIENTE]]>0,"PENDIENTE")} -> PAZ Y SALVO | AI14: CAJA DE AHORROS | AJ14: JOSE PINTO | AK14: jose.pinto@banistmo.com /62352036 | AL14: CON CPP | AO14: CON CPP | AP14: 122000 | AQ14: Reservada - Con Contrato | AR14: 45464 | AS14: =AA14 -> 152500 | AT14: 30474581 | AU14: BANCO | AV14: BANCO | AW14: =ABONOS!O15 -> 0 | AX14: {=_xlfn.IFS(Tabla4[[#This Row],[MONTO5]]=0,"",Tabla4[[#This Row],[SALDO PENDIENTE3]]=0,"PAZ Y SALVO",Tabla4[[#This Row],[SALDO PENDIENTE3]]>0,"PENDIENTE")} -> PAZ Y SALVO | AY14: INSCRITA Y DESEMBOLSADA | AZ14: 45504 | BA14: SI | BB14: 45532 | BC14: =Tabla4[[#This Row],[FECHA RECIBIDO MINUTA LIBERACION]]-Tabla4[[#This Row],[SOLICITUD DE MINUTA LIBERACIÓN]] -> 28 | BD14: SI | BE14: 45535 | BF14: SI | BG14: 45539 | BH14: SI | BI14: SI | BJ14: SI | BK14: 45573 | BL14: 45576 | BM14: 45577 | BN14: 45579 | BO14: 45581 | BP14: =Tabla4[[#This Row],[RECEPCIÓN INTERINO]]-Tabla4[[#This Row],[ENVIO A INTERINO]] -> 2 | BQ14: 45579 | BR14: 45579 | BS14: 45579 | BT14: 45579 | BU14: 45581 | BV14: SI | BW14: 45575 | BX14: 45586 | BY14: 45588 | BZ14: 45597 | CA14: 45597 | CB14: 45604 | CC14: 45604
A15: L-403 | B15: -100 | C15: CARLOS ARAGON / MILAINE DOMINGUEZ | D15: TRASPASADO | E15: INSCRITO Y DESEMBOLSADO | F15: 45658 | G15: 668069351 | H15: ESTADOUNIDENSE | I15: EXTRANJERO NO RESIDENTE | J15: MARISOL CUESTA | K15: 26279 | L15: INDEPENDIENTE | M15: ADMINISTRADOR DE EMPRESAS | N15: CONTADO | S15: C1 | T15: 73.09 | U15: 0 | V15: =U15+T15 -> 73.09 | X15: =AB15*T15 -> 179070.5 | AA15: 185270 | AB15: 2450 | AC15: =((AD15*1)/AA15) -> 0.33494856 | AD15: =SUMIFS(Tabla35[Abonos],Tabla35[Lote],Tabla4[[#This Row],[UNIDAD APTO]],Tabla35[Cliente],Tabla4[[#This Row],[CLIENTE]],Tabla35[Concepto],"ABONO")+SUMIFS(Tabla35[Abonos],Tabla35[Lote],Tabla4[[#This Row],[UNIDAD APTO]],Tabla35[Cliente],Tabla4[[#This Row],[CLIENTE]],Tabla35[Concepto],"MULTIBANK") -> 62055.92 | AE15: =Tabla4[[#This Row],[VALOR TOTAL]]-Tabla4[[#This Row],[MONTO A MULTIBANK]] -> 185270 | AF15: 0 | AG15: =ABONOS!E16 -> 123214.08 | AH15: {=_xlfn.IFS(Tabla4[[#This Row],[RESERVADAS, VENDIDAS]]="DISPONIBLE","",Tabla4[[#This Row],[SALDO PENDIENTE]]=0,"PAZ Y SALVO",Tabla4[[#This Row],[SALDO PENDIENTE]]=Tabla4[[#This Row],[MONTO CPP]],"COBRO CPP",Tabla4[[#This Row],[SALDO PENDIENTE]]>0,"PENDIENTE")} -> PENDIENTE | AI15: N/A | AJ15: N/A | AK15: N/A | AL15: N/A | AM15: N/A | AN15: N/A | AO15: N/A | AP15: N/A | AQ15: Reservada - Con Contrato | AR15: 45686 | AS15: =AA15 -> 185270 | AT15: 30474580 | AU15: BANCO | AW15: =ABONOS!O16 -> 0 | AX15: {=_xlfn.IFS(Tabla4[[#This Row],[MONTO5]]=0,"",Tabla4[[#This Row],[SALDO PENDIENTE3]]=0,"PAZ Y SALVO",Tabla4[[#This Row],[SALDO PENDIENTE3]]>0,"PENDIENTE")} | AY15: 27-07-26: Protocolo retirado firmado por cliente | AZ15: 46211 | BA15: SI | BB15: 46213 | BC15: =Tabla4[[#This Row],[FECHA RECIBIDO MINUTA LIBERACION]]-Tabla4[[#This Row],[SOLICITUD DE MINUTA LIBERACIÓN]] -> 2 | BD15: SI | BE15: 46214 | BF15: SI | BG15: 46214 | BH15: N/A | BI15: N/A | BJ15: N/A | BK15: 46230 | BL15: 46230 | BM15: 46232 | BN15: 46232 | BO15: 46232 | BP15: =Tabla4[[#This Row],[RECEPCIÓN INTERINO]]-Tabla4[[#This Row],[ENVIO A INTERINO]] -> 0 | BU15: N/A | BZ15: 46259 | CC15: 45706
A16: L-404 | B16: -100 | C16: VERA ANN MATTHEWS / RUDOLF MATTHEWS | D16: TRASPASADO | E16: INSCRITO Y DESEMBOLSADO | F16: 45831 | G16: 572606505 / A6716876 | H16: ESTADOUNIDENSE | I16: EXTRANJERO NO RESIDENTE | J16: GESPROBAN | K16: 25895 | L16: ASALARIADO | M16: TRABAJADORA SOCIAL | N16: FINANCIAMIENTO | S16: C1 | T16: 73.09 | U16: 0 | V16: =U16+T16 -> 73.09 | X16: =AB16*T16 -> 179070.5 | AA16: 191892.6 | AB16: 2450 | AC16: =((AD16*1)/AA16) -> 1 | AD16: =SUMIFS(Tabla35[Abonos],Tabla35[Lote],Tabla4[[#This Row],[UNIDAD APTO]],Tabla35[Cliente],Tabla4[[#This Row],[CLIENTE]],Tabla35[Concepto],"ABONO")+SUMIFS(Tabla35[Abonos],Tabla35[Lote],Tabla4[[#This Row],[UNIDAD APTO]],Tabla35[Cliente],Tabla4[[#This Row],[CLIENTE]],Tabla35[Concepto],"MULTIBANK") -> 191892.6 | AE16: =Tabla4[[#This Row],[VALOR TOTAL]]-Tabla4[[#This Row],[MONTO A MULTIBANK]] -> 63751.65 | AF16: 128140.95 | AG16: =ABONOS!E17 -> 0 | AH16: {=_xlfn.IFS(Tabla4[[#This Row],[RESERVADAS, VENDIDAS]]="DISPONIBLE","",Tabla4[[#This Row],[SALDO PENDIENTE]]=0,"PAZ Y SALVO",Tabla4[[#This Row],[SALDO PENDIENTE]]=Tabla4[[#This Row],[MONTO CPP]],"COBRO CPP",Tabla4[[#This Row],[SALDO PENDIENTE]]>0,"PENDIENTE")} -> PAZ Y SALVO | AI16: BANESCO | AJ16: G | AL16: CON CPP | AM16: 45806 | AN16: =Tabla4[[#This Row],[FECHA DE EMISION DE CPP]]+365 -> 46171 | AO16: CON CPP | AP16: 149384.31 | AQ16: Reservada - Con Contrato | AR16: 45805 | AS16: 191892.6 | AT16: 30474579 | AU16: BANCO | AV16: BANCO | AW16: =ABONOS!O17 -> 0 | AX16: {=_xlfn.IFS(Tabla4[[#This Row],[MONTO5]]=0,"",Tabla4[[#This Row],[SALDO PENDIENTE3]]=0,"PAZ Y SALVO",Tabla4[[#This Row],[SALDO PENDIENTE3]]>0,"PENDIENTE")} -> PAZ Y SALVO | AY16: INSCRITA Y DESEMBOLSADA | AZ16: 45828 | BA16: SI | BB16: 45835 | BC16: =Tabla4[[#This Row],[FECHA RECIBIDO MINUTA LIBERACION]]-Tabla4[[#This Row],[SOLICITUD DE MINUTA LIBERACIÓN]] -> 7 | BD16: SI | BE16: 45838 | BF16: SI | BG16: 45838 | BH16: N/A | BI16: N/A | BJ16: N/A | BK16: 45840 | BL16: 45840 | BM16: 45840 | BN16: 45841 | BO16: 45841 | BP16: =Tabla4[[#This Row],[RECEPCIÓN INTERINO]]-Tabla4[[#This Row],[ENVIO A INTERINO]] -> 0 | BQ16: 45842 | BR16: 45825 | BS16: 45842 | BT16: 45845 | BU16: 45845 | BV16: SI | BW16: BANCO | BX16: 45845 | BY16: 45849 | BZ16: 45854 | CA16: 45854 | CB16: 45856 | CC16: 45854
A17: L-405 | B17: -100 | C17: GABRIEL DIAZ / NURIA CASTILLO | D17: TRASPASADO | E17: INSCRITO Y DESEMBOLSADO | F17: 45323 | G17: 8-303-199 | H17: PANAMEÑA | I17: NACIONAL | J17: GESPROBAN | K17: 24987 | L17: INDEPENDIENTE | M17: MEDICO | N17: FINANCIAMIENTO | O17: NO | P17: NO | Q17: N/A | R17: 0 | S17: C1 | T17: 73.09 | U17: 0 | V17: =U17+T17 -> 73.09 | X17: =AB17*T17 -> 179070.5 | AA17: 180000 | AB17: 2450 | AC17: =((AD17*1)/AA17) -> 1 | AD17: =SUMIFS(Tabla35[Abonos],Tabla35[Lote],Tabla4[[#This Row],[UNIDAD APTO]],Tabla35[Cliente],Tabla4[[#This Row],[CLIENTE]],Tabla35[Concepto],"ABONO")+SUMIFS(Tabla35[Abonos],Tabla35[Lote],Tabla4[[#This Row],[UNIDAD APTO]],Tabla35[Cliente],Tabla4[[#This Row],[CLIENTE]],Tabla35[Concepto],"MULTIBANK") -> 180000 | AE17: =Tabla4[[#This Row],[VALOR TOTAL]]-Tabla4[[#This Row],[MONTO A MULTIBANK]] -> 50000 | AF17: =Tabla4[[#This Row],[MONTO CPP]] -> 130000 | AG17: =ABONOS!E18 -> 0 | AH17: {=_xlfn.IFS(Tabla4[[#This Row],[RESERVADAS, VENDIDAS]]="DISPONIBLE","",Tabla4[[#This Row],[SALDO PENDIENTE]]=0,"PAZ Y SALVO",Tabla4[[#This Row],[SALDO PENDIENTE]]=Tabla4[[#This Row],[MONTO CPP]],"COBRO CPP",Tabla4[[#This Row],[SALDO PENDIENTE]]>0,"PENDIENTE")} -> PAZ Y SALVO | AI17: BANCO GENERAL | AL17: CON CPP | AM17: 45665 | AN17: 46030 | AO17: CON CPP | AP17: 130000 | AQ17: Reservada - Con Contrato | AR17: 45490 | AS17: =AA17 -> 180000 | AT17: 30474578 | AU17: CAJA DE AHORROS | AV17: BANCO | AW17: =ABONOS!O18 -> 0 | AX17: {=_xlfn.IFS(Tabla4[[#This Row],[MONTO5]]=0,"",Tabla4[[#This Row],[SALDO PENDIENTE3]]=0,"PAZ Y SALVO",Tabla4[[#This Row],[SALDO PENDIENTE3]]>0,"PENDIENTE")} -> PAZ Y SALVO | AY17: INSCRITA Y DESEMBOLSADA | AZ17: 45665 | BA17: SI | BB17: 45673 | BC17: =Tabla4[[#This Row],[FECHA RECIBIDO MINUTA LIBERACION]]-Tabla4[[#This Row],[SOLICITUD DE MINUTA LIBERACIÓN]] -> 8 | BD17: SI | BE17: 45673 | BF17: SI | BG17: 45673 | BH17: BANCO | BI17: BANCO | BJ17: BANCO | BK17: BANCO | BL17: 45716 | BM17: 45723 | BN17: 45727 | BO17: 45729 | BP17: =Tabla4[[#This Row],[RECEPCIÓN INTERINO]]-Tabla4[[#This Row],[ENVIO A INTERINO]] -> 2 | BQ17: 45726 | BR17: 45705 | BS17: 45726 | BT17: 45726 | BU17: 45729 | BV17: SI | BW17: BANCO | BX17: 45734 | BY17: 45736 | BZ17: 45742 | CA17: 45742 | CB17: 45747 | CC17: 45610
A18: L-406 | B18: -100 | C18: JOHN ESTRELLA / MARIA ESTRELLA | D18: TRASPASADO | E18: INSCRITO Y DESEMBOLSADO | F18: 45200 | G18: HL824486 / HL824480 | H18: CANADIENSE | I18: EXTRANJERO NO RESIDENTE | J18: PANAMA EQUITY | K18: 26057 | L18: INDEPENDIENTE | M18: CONSULTORES | N18: CONTADO | O18: SI | Q18: SI | R18: 15000 | S18: C1 | T18: 73.98 | U18: 0 | V18: =U18+T18 -> 73.98 | X18: =AB18*T18 -> 181251 | AA18: 205422.3 | AB18: 2450 | AC18: =((AD18*1)/AA18) -> 1 | AD18: =SUMIFS(Tabla35[Abonos],Tabla35[Lote],Tabla4[[#This Row],[UNIDAD APTO]],Tabla35[Cliente],Tabla4[[#This Row],[CLIENTE]],Tabla35[Concepto],"ABONO")+SUMIFS(Tabla35[Abonos],Tabla35[Lote],Tabla4[[#This Row],[UNIDAD APTO]],Tabla35[Cliente],Tabla4[[#This Row],[CLIENTE]],Tabla35[Concepto],"MULTIBANK") -> 205422.3 | AE18: =Tabla4[[#This Row],[VALOR TOTAL]]-Tabla4[[#This Row],[MONTO A MULTIBANK]] -> 61626.69 | AF18: =AA18*70% -> 143795.61 | AG18: =ABONOS!E19 -> 0 | AH18: {=_xlfn.IFS(Tabla4[[#This Row],[RESERVADAS, VENDIDAS]]="DISPONIBLE","",Tabla4[[#This Row],[SALDO PENDIENTE]]=0,"PAZ Y SALVO",Tabla4[[#This Row],[SALDO PENDIENTE]]=Tabla4[[#This Row],[MONTO CPP]],"COBRO CPP",Tabla4[[#This Row],[SALDO PENDIENTE]]>0,"PENDIENTE")} -> PAZ Y SALVO | AI18: N/A | AJ18: N/A | AK18: N/A | AL18: N/A | AM18: N/A | AN18: N/A | AO18: N/A | AP18: N/A | AQ18: Reservada - Con Contrato | AR18: 45246 | AS18: =AA18 -> 205422.3 | AT18: 30474577 | AU18: GISA | AV18: 1805 | AW18: =ABONOS!O19 -> 0 | AX18: {=_xlfn.IFS(Tabla4[[#This Row],[MONTO5]]=0,"",Tabla4[[#This Row],[SALDO PENDIENTE3]]=0,"PAZ Y SALVO",Tabla4[[#This Row],[SALDO PENDIENTE3]]>0,"PENDIENTE")} -> PAZ Y SALVO | AY18: INSCRITA Y DESEMBOLSADA | AZ18: 45428 | BA18: SI | BB18: 45449 | BC18: =Tabla4[[#This Row],[FECHA RECIBIDO MINUTA LIBERACION]]-Tabla4[[#This Row],[SOLICITUD DE MINUTA LIBERACIÓN]] -> 21 | BD18: SI | BE18: 45450 | BF18: N/A | BG18: N/A | BH18: N/A | BI18: N/A | BJ18: N/A | BK18: 45449 | BL18: 45503 | BM18: 45454 | BN18: 45503 | BO18: 45526 | BP18: =Tabla4[[#This Row],[RECEPCIÓN INTERINO]]-Tabla4[[#This Row],[ENVIO A INTERINO]] -> 23 | BQ18: 45527 | BR18: 45537 | BS18: 45539 | BT18: 45531 | BU18: N/A | BV18: SI | BW18: 45450 | BX18: 45531 | BY18: 45567 | BZ18: 45568 | CA18: N/A | CB18: N/A | CC18: 45379
A19: L-407 | B19: -100 | C19: LEO MC DONOUGH / JODI ELLIOT | D19: TRASPASADO | E19: INSCRITO Y DESEMBOLSADO | F19: 45717 | G19: 5654432828 / A27056946 | H19: ESTADOUNIDENSE | I19: EXTRANJERO NO RESIDENTE | J19: DO PANAMA | K19: 22768 | L19: ASALARIADO | M19: INSTRUCTOR / ADMINISTRADOR DE EMPRESAS | N19: CONTADO | O19: SI | P19: NO | Q19: NO | S19: D | T19: 110.82 | U19: 0 | V19: =U19+T19 -> 110.82 | X19: =AB19*T19 -> 271509 | AA19: 299000 | AB19: 2450 | AC19: =((AD19*1)/AA19) -> 1 | AD19: =SUMIFS(Tabla35[Abonos],Tabla35[Lote],Tabla4[[#This Row],[UNIDAD APTO]],Tabla35[Cliente],Tabla4[[#This Row],[CLIENTE]],Tabla35[Concepto],"ABONO")+SUMIFS(Tabla35[Abonos],Tabla35[Lote],Tabla4[[#This Row],[UNIDAD APTO]],Tabla35[Cliente],Tabla4[[#This Row],[CLIENTE]],Tabla35[Concepto],"MULTIBANK") -> 299000 | AE19: =Tabla4[[#This Row],[VALOR TOTAL]]-Tabla4[[#This Row],[MONTO A MULTIBANK]] -> 89700 | AF19: =70%*AA19 -> 209300 | AG19: =ABONOS!E20 -> 0 | AH19: {=_xlfn.IFS(Tabla4[[#This Row],[RESERVADAS, VENDIDAS]]="DISPONIBLE","",Tabla4[[#This Row],[SALDO PENDIENTE]]=0,"PAZ Y SALVO",Tabla4[[#This Row],[SALDO PENDIENTE]]=Tabla4[[#This Row],[MONTO CPP]],"COBRO CPP",Tabla4[[#This Row],[SALDO PENDIENTE]]>0,"PENDIENTE")} -> PAZ Y SALVO | AI19: N/A | AJ19: N/A | AK19: N/A | AL19: N/A | AM19: N/A | AN19: N/A | AO19: N/A | AP19: N/A | AQ19: Reservada - Con Contrato | AR19: 45736 | AS19: =AA19 -> 299000 | AT19: 30474576 | AU19: GISA | AV19: 1967 | AW19: =ABONOS!O20 -> 0 | AX19: {=_xlfn.IFS(Tabla4[[#This Row],[MONTO5]]=0,"",Tabla4[[#This Row],[SALDO PENDIENTE3]]=0,"PAZ Y SALVO",Tabla4[[#This Row],[SALDO PENDIENTE3]]>0,"PENDIENTE")} -> PAZ Y SALVO | AY19: INSCRITA Y DESEMBOLSADA | AZ19: 45809 | BA19: SI | BB19: 45821 | BC19: =Tabla4[[#This Row],[FECHA RECIBIDO MINUTA LIBERACION]]-Tabla4[[#This Row],[SOLICITUD DE MINUTA LIBERACIÓN]] -> 12 | BD19: 45808 | BE19: 45808 | BF19: N/A | BG19: N/A | BH19: N/A | BI19: N/A | BJ19: N/A | BK19: 45809 | BL19: 45809 | BM19: 45833 | BN19: 45838 | BO19: 45842 | BP19: =Tabla4[[#This Row],[RECEPCIÓN INTERINO]]-Tabla4[[#This Row],[ENVIO A INTERINO]] -> 4 | BQ19: 45874 | BR19: 45859 | BS19: 45874 | BT19: 45876 | BU19: N/A | BV19: SI | BW19: 45809 | BX19: 45878 | BY19: 45887 | BZ19: 45893 | CA19: N/A | CB19: N/A | CC19: 45814
A20: L-408 | B20: -100 | C20: CONSTRUA INTERNATIONAL | D20: TRASPASADO | E20: INSCRITO Y DESEMBOLSADO | F20: 44986 | G20: 111800167 | H20: COSTARRICENSE | I20: EXTRANJERO RESIDENTE | J20: GESPROBAN | K20: 30567 | L20: INDEPENDIENTE | M20: INGENIERO | N20: CONTADO | O20: SI | P20: NO | Q20: N/A | R20: 0 | S20: D | T20: 109.27 | U20: 0 | V20: =U20+T20 -> 109.27 | X20: =AB20*T20 -> 267711.5 | AA20: =250000 -> 250000 | AB20: 2450 | AC20: =((AD20*1)/AA20) -> 1 | AD20: =SUMIFS(Tabla35[Abonos],Tabla35[Lote],Tabla4[[#This Row],[UNIDAD APTO]],Tabla35[Cliente],Tabla4[[#This Row],[CLIENTE]],Tabla35[Concepto],"ABONO")+SUMIFS(Tabla35[Abonos],Tabla35[Lote],Tabla4[[#This Row],[UNIDAD APTO]],Tabla35[Cliente],Tabla4[[#This Row],[CLIENTE]],Tabla35[Concepto],"MULTIBANK") -> 250000 | AE20: =Tabla4[[#This Row],[VALOR TOTAL]]-Tabla4[[#This Row],[MONTO A MULTIBANK]] -> 250000 | AF20: 0 | AG20: =ABONOS!E21 -> 0 | AH20: {=_xlfn.IFS(Tabla4[[#This Row],[RESERVADAS, VENDIDAS]]="DISPONIBLE","",Tabla4[[#This Row],[SALDO PENDIENTE]]=0,"PAZ Y SALVO",Tabla4[[#This Row],[SALDO PENDIENTE]]=Tabla4[[#This Row],[MONTO CPP]],"COBRO CPP",Tabla4[[#This Row],[SALDO PENDIENTE]]>0,"PENDIENTE")} -> PAZ Y SALVO | AI20: N/A | AJ20: N/A | AK20: N/A | AL20: N/A | AM20: N/A | AN20: N/A | AO20: N/A | AP20: N/A | AQ20: Reservada - Con Contrato | AR20: 45100 | AS20: =AA20 -> 250000 | AT20: 30474575 | AU20: GISA | AV20: 2078 | AW20: =ABONOS!O21 -> 0 | AX20: {=_xlfn.IFS(Tabla4[[#This Row],[MONTO5]]=0,"",Tabla4[[#This Row],[SALDO PENDIENTE3]]=0,"PAZ Y SALVO",Tabla4[[#This Row],[SALDO PENDIENTE3]]>0,"PENDIENTE")} -> PAZ Y SALVO | AY20: INSCRITA Y DESEMBOLSADA | AZ20: 45862 | BA20: SI | BB20: 45869 | BC20: =Tabla4[[#This Row],[FECHA RECIBIDO MINUTA LIBERACION]]-Tabla4[[#This Row],[SOLICITUD DE MINUTA LIBERACIÓN]] -> 7 | BD20: SI | BE20: 45637 | BF20: N/A | BG20: N/A | BH20: N/A | BI20: N/A | BJ20: N/A | BK20: 45637 | BL20: 45637 | BM20: 45637 | BN20: 45945 | BO20: 45952 | BP20: =Tabla4[[#This Row],[RECEPCIÓN INTERINO]]-Tabla4[[#This Row],[ENVIO A INTERINO]] -> 7 | BQ20: 45985 | BR20: 45968 | BS20: 45986 | BT20: 45986 | BU20: N/A | BV20: SI | BW20: 45637 | BX20: 45988 | BY20: 45992 | BZ20: 46004 | CA20: N/A | CB20: N/A | CC20: 45649
A21: L-409 | B21: -100 | C21: BOJAN MALISEVIC / ZORAN MALISEVIC | D21: TRASPASADO | E21: INSCRITO Y DESEMBOLSADO | F21: 45793 | G21: X6314258 | H21: SUIZA | I21: EXTRANJERO RESIDENTE | J21: JINELLY ROJAS | K21: 20513 | L21: INDEPENDIENTE | M21: VENTAS | N21: CONTADO | O21: SI | P21: NO | Q21: SI | R21: 15000 | S21: C1 | T21: 73.09 | U21: 0 | V21: =U21+T21 -> 73.09 | X21: =AB21*T21 -> 179070.5 | AA21: 205000 | AB21: 2450 | AC21: =((AD21*1)/AA21) -> 1 | AD21: =SUMIFS(Tabla35[Abonos],Tabla35[Lote],Tabla4[[#This Row],[UNIDAD APTO]],Tabla35[Cliente],Tabla4[[#This Row],[CLIENTE]],Tabla35[Concepto],"ABONO")+SUMIFS(Tabla35[Abonos],Tabla35[Lote],Tabla4[[#This Row],[UNIDAD APTO]],Tabla35[Cliente],Tabla4[[#This Row],[CLIENTE]],Tabla35[Concepto],"MULTIBANK") -> 205000 | AE21: =Tabla4[[#This Row],[VALOR TOTAL]]-Tabla4[[#This Row],[MONTO A MULTIBANK]] -> 155000 | AF21: 50000 | AG21: =ABONOS!E22 -> 0 | AH21: {=_xlfn.IFS(Tabla4[[#This Row],[RESERVADAS, VENDIDAS]]="DISPONIBLE","",Tabla4[[#This Row],[SALDO PENDIENTE]]=0,"PAZ Y SALVO",Tabla4[[#This Row],[SALDO PENDIENTE]]=Tabla4[[#This Row],[MONTO CPP]],"COBRO CPP",Tabla4[[#This Row],[SALDO PENDIENTE]]>0,"PENDIENTE")} -> PAZ Y SALVO | AI21: N/A | AJ21: N/A | AK21: N/A | AL21: N/A | AM21: N/A | AN21: N/A | AO21: N/A | AP21: N/A | AQ21: Reservada - Con Contrato | AR21: 45800 | AS21: =AA21 -> 205000 | AT21: 30474574 | AU21: GISA | AV21: 1900 | AW21: =ABONOS!O22 -> 0 | AX21: {=_xlfn.IFS(Tabla4[[#This Row],[MONTO5]]=0,"",Tabla4[[#This Row],[SALDO PENDIENTE3]]=0,"PAZ Y SALVO",Tabla4[[#This Row],[SALDO PENDIENTE3]]>0,"PENDIENTE")} -> PAZ Y SALVO | AY21: INSCRITA Y DESEMBOLSADA | AZ21: 45875 | BA21: SI | BB21: 45881 | BC21: =Tabla4[[#This Row],[FECHA RECIBIDO MINUTA LIBERACION]]-Tabla4[[#This Row],[SOLICITUD DE MINUTA LIBERACIÓN]] -> 6 | BD21: SI | BE21: 45883 | BF21: N/A | BG21: N/A | BH21: N/A | BI21: N/A | BJ21: N/A | BK21: 45889 | BL21: 45920 | BM21: 45892 | BN21: 45940 | BO21: 45950 | BP21: =Tabla4[[#This Row],[RECEPCIÓN INTERINO]]-Tabla4[[#This Row],[ENVIO A INTERINO]] -> 10 | BQ21: 45950 | BR21: 45931 | BS21: 45951 | BT21: 45951 | BU21: N/A | BV21: SI | BW21: 45951 | BX21: 45951 | BY21: 45959 | BZ21: 45961 | CA21: N/A | CB21: N/A | CC21: 45892
A22: L-410 | B22: -100 | C22: MICHAEL BELANGER | D22: TRASPASADO | E22: INSCRITO Y DESEMBOLSADO | F22: 45108 | G22: 8-812-1508 | H22: PANAMEÑA | I22: NACIONAL | J22: BELANGER REALTY PANAMA | K22: 32177 | L22: ASALARIADO | M22: COMUNICADOR CORPORATIVO | N22: CONTADO | O22: SI | P22: NO | Q22: NO | R22: 12000 | S22: B | T22: 59.94 | U22: 0 | V22: =U22+T22 -> 59.94 | X22: =AB22*T22 -> 146853 | AA22: =X22+W22+Y22+Z22 -> 146853 | AB22: 2450 | AC22: =((AD22*1)/AA22) -> 1 | AD22: =SUMIFS(Tabla35[Abonos],Tabla35[Lote],Tabla4[[#This Row],[UNIDAD APTO]],Tabla35[Cliente],Tabla4[[#This Row],[CLIENTE]],Tabla35[Concepto],"ABONO")+SUMIFS(Tabla35[Abonos],Tabla35[Lote],Tabla4[[#This Row],[UNIDAD APTO]],Tabla35[Cliente],Tabla4[[#This Row],[CLIENTE]],Tabla35[Concepto],"MULTIBANK") -> 146853 | AE22: =Tabla4[[#This Row],[VALOR TOTAL]]-Tabla4[[#This Row],[MONTO A MULTIBANK]] -> 44055.9 | AF22: =AA22*70% -> 102797.1 | AG22: =ABONOS!E23 -> 0 | AH22: {=_xlfn.IFS(Tabla4[[#This Row],[RESERVADAS, VENDIDAS]]="DISPONIBLE","",Tabla4[[#This Row],[SALDO PENDIENTE]]=0,"PAZ Y SALVO",Tabla4[[#This Row],[SALDO PENDIENTE]]=Tabla4[[#This Row],[MONTO CPP]],"COBRO CPP",Tabla4[[#This Row],[SALDO PENDIENTE]]>0,"PENDIENTE")} -> PAZ Y SALVO | AI22: N/A | AJ22: N/A | AK22: N/A | AL22: N/A | AM22: N/A | AN22: N/A | AO22: N/A | AP22: N/A | AQ22: Reservada - Con Contrato | AR22: 45167 | AS22: =AA22 -> 146853 | AT22: 30474573 | AU22: GISA | AV22: 450 | AW22: =ABONOS!O23 -> 0 | AX22: {=_xlfn.IFS(Tabla4[[#This Row],[MONTO5]]=0,"",Tabla4[[#This Row],[SALDO PENDIENTE3]]=0,"PAZ Y SALVO",Tabla4[[#This Row],[SALDO PENDIENTE3]]>0,"PENDIENTE")} -> PAZ Y SALVO | AY22: INSCRITA Y DESEMBOLSADA | AZ22: 45485 | BA22: SI | BB22: 45497 | BC22: =Tabla4[[#This Row],[FECHA RECIBIDO MINUTA LIBERACION]]-Tabla4[[#This Row],[SOLICITUD DE MINUTA LIBERACIÓN]] -> 12 | BD22: SI | BE22: 45499 | BF22: N/A | BG22: N/A | BH22: N/A | BI22: N/A | BJ22: N/A | BK22: 45503 | BL22: 45543 | BM22: 45524 | BN22: 45530 | BO22: 45534 | BP22: =Tabla4[[#This Row],[RECEPCIÓN INTERINO]]-Tabla4[[#This Row],[ENVIO A INTERINO]] -> 4 | BQ22: 45540 | BR22: 45540 | BS22: 45539 | BT22: 45540 | BU22: N/A | BV22: SI | BW22: 45505 | BX22: 45544 | BY22: 45551 | BZ22: 45553 | CA22: N/A | CB22: N/A | CC22: 45548
A23: L-411 | B23: -100 | C23: KOYNE LOISELLE | D23: TRASPASADO | E23: INSCRITO Y DESEMBOLSADO | F23: 44986 | G23: HD813149 | H23: CANADIENSE | I23: EXTRANJERO NO RESIDENTE | J23: PANAMA PACIFICA REALTY | K23: 25833 | L23: INDEPENDIENTE | M23: BIENES RAICES | N23: CONTADO | O23: SI | P23: NO | Q23: N/A | S23: A | T23: 65.93 | U23: 0 | V23: =U23+T23 -> 65.93 | X23: =AB23*T23 -> 161528.5 | AA23: =X23+W23+Y23+Z23 -> 161528.5 | AB23: 2450 | AC23: =((AD23*1)/AA23) -> 1 | AD23: =SUMIFS(Tabla35[Abonos],Tabla35[Lote],Tabla4[[#This Row],[UNIDAD APTO]],Tabla35[Cliente],Tabla4[[#This Row],[CLIENTE]],Tabla35[Concepto],"ABONO")+SUMIFS(Tabla35[Abonos],Tabla35[Lote],Tabla4[[#This Row],[UNIDAD APTO]],Tabla35[Cliente],Tabla4[[#This Row],[CLIENTE]],Tabla35[Concepto],"MULTIBANK") -> 161528.5 | AE23: =Tabla4[[#This Row],[VALOR TOTAL]]-Tabla4[[#This Row],[MONTO A MULTIBANK]] -> 48458.55 | AF23: =AA23*70% -> 113069.95 | AG23: =ABONOS!E24 -> 0 | AH23: {=_xlfn.IFS(Tabla4[[#This Row],[RESERVADAS, VENDIDAS]]="DISPONIBLE","",Tabla4[[#This Row],[SALDO PENDIENTE]]=0,"PAZ Y SALVO",Tabla4[[#This Row],[SALDO PENDIENTE]]=Tabla4[[#This Row],[MONTO CPP]],"COBRO CPP",Tabla4[[#This Row],[SALDO PENDIENTE]]>0,"PENDIENTE")} -> PAZ Y SALVO | AI23: N/A | AJ23: N/A | AK23: N/A | AL23: N/A | AM23: N/A | AN23: N/A | AO23: N/A | AP23: N/A | AQ23: Reservada - Con Contrato | AR23: 45073 | AS23: =AA23 -> 161528.5 | AT23: 30474572 | AU23: GISA | AV23: 1550 | AW23: =ABONOS!O24 -> 77.1 | AX23: {=_xlfn.IFS(Tabla4[[#This Row],[MONTO5]]=0,"",Tabla4[[#This Row],[SALDO PENDIENTE3]]=0,"PAZ Y SALVO",Tabla4[[#This Row],[SALDO PENDIENTE3]]>0,"PENDIENTE")} -> PENDIENTE | AY23: INSCRITA Y DESEMBOLSADA | AZ23: 45455 | BA23: SI | BB23: 45495 | BC23: =Tabla4[[#This Row],[FECHA RECIBIDO MINUTA LIBERACION]]-Tabla4[[#This Row],[SOLICITUD DE MINUTA LIBERACIÓN]] -> 40 | BD23: SI | BE23: 45458 | BF23: N/A | BG23: N/A | BH23: N/A | BI23: N/A | BJ23: N/A | BK23: 45510 | BL23: 45517 | BM23: 45510 | BN23: 45530 | BO23: 45533 | BP23: =Tabla4[[#This Row],[RECEPCIÓN INTERINO]]-Tabla4[[#This Row],[ENVIO A INTERINO]] -> 3 | BQ23: 45544 | BR23: 45540 | BS23: 45539 | BT23: 45545 | BU23: N/A | BV23: SI | BW23: 45511 | BX23: 45546 | BY23: 45547 | BZ23: 45553 | CA23: N/A | CB23: N/A | CC23: 45511
A24: L-301 | B24: -200 | C24: SCOTT WAYNE / THI LE NETTIE | D24: TRASPASADO | E24: INSCRITO Y DESEMBOLSADO | F24: 45170 | G24: E-8-204924 / E-8-204917 | H24: CANADIENSE | I24: EXTRANJERO NO RESIDENTE | J24: PANAMA EQUITY | K24: 23264 | L24: INDEPENDIENTE | M24: ADMINISTRADOR DE EMPRESAS | N24: CONTADO | O24: SI | P24: SI | Q24: SI | R24: 14000 | S24: A | T24: 65.93 | U24: 0 | V24: =U24+T24 -> 65.93 | X24: 202000 | AA24: =X24+W24+Y24+Z24 -> 202000 | AB24: 2400 | AC24: =((AD24*1)/AA24) -> 1 | AD24: =SUMIFS(Tabla35[Abonos],Tabla35[Lote],Tabla4[[#This Row],[UNIDAD APTO]],Tabla35[Cliente],Tabla4[[#This Row],[CLIENTE]],Tabla35[Concepto],"ABONO")+SUMIFS(Tabla35[Abonos],Tabla35[Lote],Tabla4[[#This Row],[UNIDAD APTO]],Tabla35[Cliente],Tabla4[[#This Row],[CLIENTE]],Tabla35[Concepto],"MULTIBANK") -> 202000 | AE24: =Tabla4[[#This Row],[VALOR TOTAL]]-Tabla4[[#This Row],[MONTO A MULTIBANK]] -> 70700 | AF24: =AA24*65% -> 131300 | AG24: =ABONOS!E25 -> 0 | AH24: {=_xlfn.IFS(Tabla4[[#This Row],[RESERVADAS, VENDIDAS]]="DISPONIBLE","",Tabla4[[#This Row],[SALDO PENDIENTE]]=0,"PAZ Y SALVO",Tabla4[[#This Row],[SALDO PENDIENTE]]=Tabla4[[#This Row],[MONTO CPP]],"COBRO CPP",Tabla4[[#This Row],[SALDO PENDIENTE]]>0,"PENDIENTE")} -> PAZ Y SALVO | AI24: TOWERBANK | AJ24: N/A | AK24: N/A | AL24: CON CPP | AM24: 45456 | AN24: 45635 | AO24: FONDO PROPIOS PIGNORADOS | AP24: 73016.96 | AQ24: Reservada - Con Contrato | AR24: 45229 | AS24: =AA24 -> 202000 | AT24: 30474594 | AU24: GISA | AV24: 1870 | AW24: =ABONOS!O25 -> 0 | AX24: {=_xlfn.IFS(Tabla4[[#This Row],[MONTO5]]=0,"",Tabla4[[#This Row],[SALDO PENDIENTE3]]=0,"PAZ Y SALVO",Tabla4[[#This Row],[SALDO PENDIENTE3]]>0,"PENDIENTE")} -> PAZ Y SALVO | AY24: INSCRITA Y DESEMBOLSADA | AZ24: 45478 | BA24: SI | BB24: 45497 | BC24: =Tabla4[[#This Row],[FECHA RECIBIDO MINUTA LIBERACION]]-Tabla4[[#This Row],[SOLICITUD DE MINUTA LIBERACIÓN]] -> 19 | BD24: SI | BE24: 45497 | BF24: N/A | BG24: N/A | BH24: N/A | BI24: N/A | BJ24: N/A | BK24: 45502 | BL24: 45533 | BM24: 45533 | BN24: 45533 | BO24: 45539 | BP24: =Tabla4[[#This Row],[RECEPCIÓN INTERINO]]-Tabla4[[#This Row],[ENVIO A INTERINO]] -> 6 | BQ24: 45544 | BR24: 45539 | BS24: 45539 | BT24: 45545 | BU24: N/A | BV24: SI | BW24: 45502 | BX24: 45546 | BY24: 45559 | BZ24: 45560 | CA24: 45560 | CB24: 45567 | CC24: 45536
A25: L-302 | B25: -200 | C25: CARLOS ARAGON | D25: TRASPASADO | E25: INSCRITO Y DESEMBOLSADO | F25: 45292 | G25: 668069351 | H25: ESTADOUNIDENSE | I25: EXTRANJERO NO RESIDENTE | J25: MARISOL CUESTA Y BELANGER REALTY PANAMA S.A. | K25: 26279 | L25: INDEPENDIENTE | M25: ADMINISTRADOR DE EMPRESAS | N25: CONTADO | O25: SI | P25: NO | Q25: N/A | R25: N/A | S25: B | T25: 59.94 | U25: 0 | V25: =U25+T25 -> 59.94 | X25: =AB25*T25 -> 143856 | AA25: 145000 | AB25: 2400 | AC25: =((AD25*1)/AA25) -> 0.99960621 | AD25: =SUMIFS(Tabla35[Abonos],Tabla35[Lote],Tabla4[[#This Row],[UNIDAD APTO]],Tabla35[Cliente],Tabla4[[#This Row],[CLIENTE]],Tabla35[Concepto],"ABONO")+SUMIFS(Tabla35[Abonos],Tabla35[Lote],Tabla4[[#This Row],[UNIDAD APTO]],Tabla35[Cliente],Tabla4[[#This Row],[CLIENTE]],Tabla35[Concepto],"MULTIBANK") -> 144942.9 | AE25: =Tabla4[[#This Row],[VALOR TOTAL]]-Tabla4[[#This Row],[MONTO A MULTIBANK]] -> 145000 | AF25: 0 | AG25: =ABONOS!E26 -> 57.1 | AH25: {=_xlfn.IFS(Tabla4[[#This Row],[RESERVADAS, VENDIDAS]]="DISPONIBLE","",Tabla4[[#This Row],[SALDO PENDIENTE]]=0,"PAZ Y SALVO",Tabla4[[#This Row],[SALDO PENDIENTE]]=Tabla4[[#This Row],[MONTO CPP]],"COBRO CPP",Tabla4[[#This Row],[SALDO PENDIENTE]]>0,"PENDIENTE")} -> PENDIENTE | AI25: N/A | AJ25: N/A | AK25: N/A | AL25: N/A | AM25: N/A | AN25: N/A | AO25: ACUERDO FINANCIAMIENTO INTERNO | AP25: N/A | AQ25: Reservada - Con Contrato | AR25: 45464 | AS25: =AA25 -> 145000 | AT25: 30474593 | AU25: GISA | AV25: 1593 | AW25: =ABONOS!O26 -> 0 | AX25: {=_xlfn.IFS(Tabla4[[#This Row],[MONTO5]]=0,"",Tabla4[[#This Row],[SALDO PENDIENTE3]]=0,"PAZ Y SALVO",Tabla4[[#This Row],[SALDO PENDIENTE3]]>0,"PENDIENTE")} -> PAZ Y SALVO | AY25: INSCRITA Y DESEMBOLSADA | AZ25: 45862 | BA25: SI | BB25: 45869 | BC25: =Tabla4[[#This Row],[FECHA RECIBIDO MINUTA LIBERACION]]-Tabla4[[#This Row],[SOLICITUD DE MINUTA LIBERACIÓN]] -> 7 | BD25: SI | BE25: 45967 | BF25: N/A | BG25: N/A | BH25: N/A | BI25: N/A | BJ25: N | BK25: 45967 | BL25: 45969 | BM25: 45969 | BN25: 45975 | BO25: 45984 | BP25: =Tabla4[[#This Row],[RECEPCIÓN INTERINO]]-Tabla4[[#This Row],[ENVIO A INTERINO]] -> 9 | BQ25: 45985 | BR25: 45968 | BS25: 45986 | BT25: 45986 | BU25: N/A | BV25: SI | BW25: 45969 | BX25: 45988 | BY25: 45988 | BZ25: 45996 | CA25: N/A | CB25: N/A | CC25: 45478
